Fri, 15 Apr 2022 15:02:35-_jb_pytest_runner.py-Assert.py-[line:110]-ERROR-[日志信息]: Traceback (most recent call last):
  File "C:\Users\张铁瀛\PycharmProjects\API_AUTO\common\Assert.py", line 104, in define_assert
    assert res['code'] == respData['code']
AssertionError: assert 'RecordNotFoundError' == 'Success'

Fri, 15 Apr 2022 15:05:21-_jb_pytest_runner.py-Assert.py-[line:110]-ERROR-[日志信息]: Traceback (most recent call last):
  File "C:\Users\张铁瀛\PycharmProjects\API_AUTO\common\Assert.py", line 104, in define_assert
    assert res['code'] == respData['code']
AssertionError: assert 'RecordNotFoundError' == 'Success'

Fri, 15 Apr 2022 15:11:33-_jb_pytest_runner.py-Assert.py-[line:110]-ERROR-[日志信息]: Traceback (most recent call last):
  File "C:\Users\张铁瀛\PycharmProjects\API_AUTO\common\Assert.py", line 104, in define_assert
    assert res['code'] == respData['code']
AssertionError: assert 'RecordNotFoundError' == 'Success'

Fri, 15 Apr 2022 15:27:39-_jb_pytest_runner.py-Assert.py-[line:110]-ERROR-[日志信息]: Traceback (most recent call last):
  File "C:\Users\张铁瀛\PycharmProjects\API_AUTO\common\Assert.py", line 104, in define_assert
    assert res['code'] == respData['code']
AssertionError: assert 'RecordNotFoundError' == 'Success'

Fri, 15 Apr 2022 15:30:21-_jb_pytest_runner.py-Assert.py-[line:110]-ERROR-[日志信息]: Traceback (most recent call last):
  File "C:\Users\张铁瀛\PycharmProjects\API_AUTO\common\Assert.py", line 104, in define_assert
    assert res['code'] == respData['code']
AssertionError: assert 'ServerError' == 'Success'

Fri, 15 Apr 2022 15:32:49-_jb_pytest_runner.py-Assert.py-[line:110]-ERROR-[日志信息]: Traceback (most recent call last):
  File "C:\Users\张铁瀛\PycharmProjects\API_AUTO\common\Assert.py", line 104, in define_assert
    assert res['code'] == respData['code']
AssertionError: assert 'RecordNotFoundError' == 'Success'

Fri, 15 Apr 2022 15:35:30-_jb_pytest_runner.py-Assert.py-[line:110]-ERROR-[日志信息]: Traceback (most recent call last):
  File "C:\Users\张铁瀛\PycharmProjects\API_AUTO\common\Assert.py", line 104, in define_assert
    assert res['code'] == respData['code']
AssertionError: assert 'RecordNotFoundError' == 'Success'

Fri, 15 Apr 2022 15:41:47-_jb_pytest_runner.py-Assert.py-[line:110]-ERROR-[日志信息]: Traceback (most recent call last):
  File "C:\Users\张铁瀛\PycharmProjects\API_AUTO\common\Assert.py", line 104, in define_assert
    assert res['code'] == respData['code']
AssertionError: assert 'RecordNotFoundError' == 'Success'

Fri, 15 Apr 2022 15:43:47-_jb_pytest_runner.py-Assert.py-[line:110]-ERROR-[日志信息]: Traceback (most recent call last):
  File "C:\Users\张铁瀛\PycharmProjects\API_AUTO\common\Assert.py", line 104, in define_assert
    assert res['code'] == respData['code']
AssertionError: assert 'DatabaseError' == 'Success'

Fri, 15 Apr 2022 15:50:07-_jb_pytest_runner.py-Assert.py-[line:110]-ERROR-[日志信息]: Traceback (most recent call last):
  File "C:\Users\张铁瀛\PycharmProjects\API_AUTO\common\Assert.py", line 104, in define_assert
    assert res['code'] == respData['code']
AssertionError: assert 'RequestParameterIsWrong' == 'Success'

Fri, 15 Apr 2022 17:54:57-_jb_pytest_runner.py-Assert.py-[line:110]-ERROR-[日志信息]: Traceback (most recent call last):
  File "C:\Users\张铁瀛\PycharmProjects\API_AUTO\common\Assert.py", line 104, in define_assert
    assert res['code'] == respData['code']
AssertionError: assert 'RecordNotFoundError' == 'InternalError'

Fri, 15 Apr 2022 17:59:36-_jb_pytest_runner.py-Assert.py-[line:110]-ERROR-[日志信息]: Traceback (most recent call last):
  File "C:\Users\张铁瀛\PycharmProjects\API_AUTO\common\Assert.py", line 104, in define_assert
    assert res['code'] == respData['code']
AssertionError: assert 'RecordNotFoundError' == 'InternalError'

Fri, 15 Apr 2022 18:00:47-_jb_pytest_runner.py-Assert.py-[line:110]-ERROR-[日志信息]: Traceback (most recent call last):
  File "C:\Users\张铁瀛\PycharmProjects\API_AUTO\common\Assert.py", line 104, in define_assert
    assert res['code'] == respData['code']
AssertionError: assert 'RecordNotFoundError' == 'InternalError'

Fri, 15 Apr 2022 18:08:26-_jb_pytest_runner.py-Assert.py-[line:110]-ERROR-[日志信息]: Traceback (most recent call last):
  File "C:\Users\张铁瀛\PycharmProjects\API_AUTO\common\Assert.py", line 104, in define_assert
    assert res['code'] == respData['code']
AssertionError: assert 'RecordNotFoundError' == 'InternalError'

