Mon, 14 Mar 2022 10:58:32-_jb_pytest_runner.py-test_InstanceCase.py-[line:36]-INFO-[日志信息]: 当前用例名称：正确创建实例
Mon, 14 Mar 2022 10:58:32-_jb_pytest_runner.py-test_InstanceCase.py-[line:37]-INFO-[日志信息]: 当前测试用例请求参数：{'instance_info': {'charge_type': 'payg', 'image': 'hub.kce.ksyun.com/autodl-image/torch:cuda11.0-cudnn8-devel-ubuntu18.04-py38-torch1.7.0', 'machine_id': '0', 'instance_name': '', 'req_gpu_amount': 1}, 'price_info': {'charge_type': 'payg', 'duration': 1, 'machine_id': '0', 'num': 1}}
Mon, 14 Mar 2022 10:58:32-_jb_pytest_runner.py-test_InstanceCase.py-[line:38]-INFO-[日志信息]: 当前用例预期结果：{'code': 'Success', 'msg': ''}
Mon, 14 Mar 2022 10:58:32-_jb_pytest_runner.py-test_InstanceCase.py-[line:39]-INFO-[日志信息]: 当前用例实际结果：{'code': 'DatabaseError', 'data': None, 'msg': '服务异常，请稍后重试', 'debug_error': ''}

Mon, 14 Mar 2022 10:58:32-_jb_pytest_runner.py-Assert.py-[line:110]-ERROR-[日志信息]: Traceback (most recent call last):
  File "C:\Users\张铁瀛\PycharmProjects\API_AUTO\common\Assert.py", line 104, in define_assert
    assert res['code'] == respData['code']
AssertionError: assert 'DatabaseError' == 'Success'

Mon, 14 Mar 2022 10:58:32-_jb_pytest_runner.py-test_InstanceCase.py-[line:43]-ERROR-[日志信息]: 用例执行失败assert 'DatabaseError' == 'Success'
Mon, 14 Mar 2022 10:58:33-_jb_pytest_runner.py-test_InstanceCase.py-[line:36]-INFO-[日志信息]: 当前用例名称：创建实例时GPU不足
Mon, 14 Mar 2022 10:58:33-_jb_pytest_runner.py-test_InstanceCase.py-[line:37]-INFO-[日志信息]: 当前测试用例请求参数：{'instance_info': {'charge_type': 'payg', 'image': 'hub.kce.ksyun.com/autodl-image/torch:cuda11.0-cudnn8-devel-ubuntu18.04-py38-torch1.7.0', 'machine_id': '0', 'instance_name': '', 'req_gpu_amount': 1}, 'price_info': {'charge_type': 'payg', 'duration': 1, 'machine_id': '0', 'num': 1}}
Mon, 14 Mar 2022 10:58:33-_jb_pytest_runner.py-test_InstanceCase.py-[line:38]-INFO-[日志信息]: 当前用例预期结果：{'code': 'InternalError', 'msg': '机器空闲GPU不足'}
Mon, 14 Mar 2022 10:58:33-_jb_pytest_runner.py-test_InstanceCase.py-[line:39]-INFO-[日志信息]: 当前用例实际结果：{'code': 'DatabaseError', 'data': None, 'msg': '服务异常，请稍后重试', 'debug_error': ''}

Mon, 14 Mar 2022 10:58:33-_jb_pytest_runner.py-Assert.py-[line:110]-ERROR-[日志信息]: Traceback (most recent call last):
  File "C:\Users\张铁瀛\PycharmProjects\API_AUTO\common\Assert.py", line 104, in define_assert
    assert res['code'] == respData['code']
AssertionError: assert 'DatabaseError' == 'InternalError'

Mon, 14 Mar 2022 10:58:33-_jb_pytest_runner.py-test_InstanceCase.py-[line:43]-ERROR-[日志信息]: 用例执行失败assert 'DatabaseError' == 'InternalError'
Mon, 14 Mar 2022 11:03:53-_jb_pytest_runner.py-test_InstanceCase.py-[line:36]-INFO-[日志信息]: 当前用例名称：正确创建实例
Mon, 14 Mar 2022 11:03:53-_jb_pytest_runner.py-test_InstanceCase.py-[line:37]-INFO-[日志信息]: 当前测试用例请求参数：{'instance_info': {'charge_type': 'payg', 'image': 'hub.kce.ksyun.com/autodl-image/torch:cuda11.0-cudnn8-devel-ubuntu18.04-py38-torch1.7.0', 'machine_id': '1', 'instance_name': '', 'req_gpu_amount': 1}, 'price_info': {'charge_type': 'payg', 'duration': 1, 'machine_id': '1', 'num': 1}}
Mon, 14 Mar 2022 11:03:53-_jb_pytest_runner.py-test_InstanceCase.py-[line:38]-INFO-[日志信息]: 当前用例预期结果：{'code': 'Success', 'msg': ''}
Mon, 14 Mar 2022 11:03:53-_jb_pytest_runner.py-test_InstanceCase.py-[line:39]-INFO-[日志信息]: 当前用例实际结果：{'code': 'DatabaseError', 'data': None, 'msg': '服务异常，请稍后重试', 'debug_error': ''}

Mon, 14 Mar 2022 11:03:53-_jb_pytest_runner.py-Assert.py-[line:110]-ERROR-[日志信息]: Traceback (most recent call last):
  File "C:\Users\张铁瀛\PycharmProjects\API_AUTO\common\Assert.py", line 104, in define_assert
    assert res['code'] == respData['code']
AssertionError: assert 'DatabaseError' == 'Success'

Mon, 14 Mar 2022 11:03:53-_jb_pytest_runner.py-test_InstanceCase.py-[line:43]-ERROR-[日志信息]: 用例执行失败assert 'DatabaseError' == 'Success'
Mon, 14 Mar 2022 11:03:53-_jb_pytest_runner.py-test_InstanceCase.py-[line:36]-INFO-[日志信息]: 当前用例名称：创建实例时GPU不足
Mon, 14 Mar 2022 11:03:53-_jb_pytest_runner.py-test_InstanceCase.py-[line:37]-INFO-[日志信息]: 当前测试用例请求参数：{'instance_info': {'charge_type': 'payg', 'image': 'hub.kce.ksyun.com/autodl-image/torch:cuda11.0-cudnn8-devel-ubuntu18.04-py38-torch1.7.0', 'machine_id': '1', 'instance_name': '', 'req_gpu_amount': 1}, 'price_info': {'charge_type': 'payg', 'duration': 1, 'machine_id': '1', 'num': 1}}
Mon, 14 Mar 2022 11:03:53-_jb_pytest_runner.py-test_InstanceCase.py-[line:38]-INFO-[日志信息]: 当前用例预期结果：{'code': 'InternalError', 'msg': '机器空闲GPU不足'}
Mon, 14 Mar 2022 11:03:53-_jb_pytest_runner.py-test_InstanceCase.py-[line:39]-INFO-[日志信息]: 当前用例实际结果：{'code': 'DatabaseError', 'data': None, 'msg': '服务异常，请稍后重试', 'debug_error': ''}

Mon, 14 Mar 2022 11:03:53-_jb_pytest_runner.py-Assert.py-[line:110]-ERROR-[日志信息]: Traceback (most recent call last):
  File "C:\Users\张铁瀛\PycharmProjects\API_AUTO\common\Assert.py", line 104, in define_assert
    assert res['code'] == respData['code']
AssertionError: assert 'DatabaseError' == 'InternalError'

Mon, 14 Mar 2022 11:03:53-_jb_pytest_runner.py-test_InstanceCase.py-[line:43]-ERROR-[日志信息]: 用例执行失败assert 'DatabaseError' == 'InternalError'
Mon, 14 Mar 2022 14:05:44-_jb_pytest_runner.py-test_InstanceCase.py-[line:36]-INFO-[日志信息]: 当前用例名称：正确创建实例
Mon, 14 Mar 2022 14:05:44-_jb_pytest_runner.py-test_InstanceCase.py-[line:37]-INFO-[日志信息]: 当前测试用例请求参数：{'instance_info': {'charge_type': 'payg', 'image': 'hub.kce.ksyun.com/autodl-image/torch:cuda11.0-cudnn8-devel-ubuntu18.04-py38-torch1.7.0', 'machine_id': 'f94411a60c', 'instance_name': '', 'req_gpu_amount': 1}, 'price_info': {'charge_type': 'payg', 'duration': 1, 'machine_id': 'f94411a60c', 'num': 1}}
Mon, 14 Mar 2022 14:05:44-_jb_pytest_runner.py-test_InstanceCase.py-[line:38]-INFO-[日志信息]: 当前用例预期结果：{'code': 'Success', 'msg': ''}
Mon, 14 Mar 2022 14:05:44-_jb_pytest_runner.py-test_InstanceCase.py-[line:39]-INFO-[日志信息]: 当前用例实际结果：{'code': 'Success', 'data': 'f94411a60c-9157cb85', 'msg': ''}

Mon, 14 Mar 2022 14:05:45-_jb_pytest_runner.py-test_InstanceCase.py-[line:36]-INFO-[日志信息]: 当前用例名称：创建实例时GPU不足
Mon, 14 Mar 2022 14:05:45-_jb_pytest_runner.py-test_InstanceCase.py-[line:37]-INFO-[日志信息]: 当前测试用例请求参数：{'instance_info': {'charge_type': 'payg', 'image': 'hub.kce.ksyun.com/autodl-image/torch:cuda11.0-cudnn8-devel-ubuntu18.04-py38-torch1.7.0', 'machine_id': '875111ae0c', 'instance_name': '', 'req_gpu_amount': 1}, 'price_info': {'charge_type': 'payg', 'duration': 1, 'machine_id': '875111ae0c', 'num': 1}}
Mon, 14 Mar 2022 14:05:45-_jb_pytest_runner.py-test_InstanceCase.py-[line:38]-INFO-[日志信息]: 当前用例预期结果：{'code': 'InternalError', 'msg': '机器空闲GPU不足'}
Mon, 14 Mar 2022 14:05:45-_jb_pytest_runner.py-test_InstanceCase.py-[line:39]-INFO-[日志信息]: 当前用例实际结果：{'code': 'InternalError', 'data': None, 'msg': '机器空闲GPU不足', 'debug_error': ''}

Mon, 14 Mar 2022 14:12:02-_jb_pytest_runner.py-test_InstanceCase.py-[line:36]-INFO-[日志信息]: 当前用例名称：正确创建实例
Mon, 14 Mar 2022 14:12:02-_jb_pytest_runner.py-test_InstanceCase.py-[line:37]-INFO-[日志信息]: 当前测试用例请求参数：{'instance_info': {'charge_type': 'payg', 'image': 'hub.kce.ksyun.com/autodl-image/torch:cuda11.0-cudnn8-devel-ubuntu18.04-py38-torch1.7.0', 'machine_id': 'f94411a60c', 'instance_name': '', 'req_gpu_amount': 1}, 'price_info': {'charge_type': 'payg', 'duration': 1, 'machine_id': 'f94411a60c', 'num': 1}}
Mon, 14 Mar 2022 14:12:02-_jb_pytest_runner.py-test_InstanceCase.py-[line:38]-INFO-[日志信息]: 当前用例预期结果：{'code': 'Success', 'msg': ''}
Mon, 14 Mar 2022 14:12:02-_jb_pytest_runner.py-test_InstanceCase.py-[line:39]-INFO-[日志信息]: 当前用例实际结果：{'code': 'Success', 'data': 'f94411a60c-6715bb62', 'msg': ''}

Mon, 14 Mar 2022 14:12:05-_jb_pytest_runner.py-test_InstanceCase.py-[line:36]-INFO-[日志信息]: 当前用例名称：创建实例时GPU不足
Mon, 14 Mar 2022 14:12:05-_jb_pytest_runner.py-test_InstanceCase.py-[line:37]-INFO-[日志信息]: 当前测试用例请求参数：{'instance_info': {'charge_type': 'payg', 'image': 'hub.kce.ksyun.com/autodl-image/torch:cuda11.0-cudnn8-devel-ubuntu18.04-py38-torch1.7.0', 'machine_id': '875111ae0c', 'instance_name': '', 'req_gpu_amount': 1}, 'price_info': {'charge_type': 'payg', 'duration': 1, 'machine_id': '875111ae0c', 'num': 1}}
Mon, 14 Mar 2022 14:12:05-_jb_pytest_runner.py-test_InstanceCase.py-[line:38]-INFO-[日志信息]: 当前用例预期结果：{'code': 'InternalError', 'msg': '机器空闲GPU不足'}
Mon, 14 Mar 2022 14:12:05-_jb_pytest_runner.py-test_InstanceCase.py-[line:39]-INFO-[日志信息]: 当前用例实际结果：{'code': 'InternalError', 'data': None, 'msg': '机器空闲GPU不足', 'debug_error': ''}

Mon, 14 Mar 2022 14:18:47-_jb_pytest_runner.py-test_InstanceCase.py-[line:36]-INFO-[日志信息]: 当前用例名称：正确创建实例
Mon, 14 Mar 2022 14:18:47-_jb_pytest_runner.py-test_InstanceCase.py-[line:37]-INFO-[日志信息]: 当前测试用例请求参数：{'instance_info': {'charge_type': 'payg', 'image': 'hub.kce.ksyun.com/autodl-image/torch:cuda11.0-cudnn8-devel-ubuntu18.04-py38-torch1.7.0', 'machine_id': 'f94411a60c', 'instance_name': '', 'req_gpu_amount': 1}, 'price_info': {'charge_type': 'payg', 'duration': 1, 'machine_id': 'f94411a60c', 'num': 1}}
Mon, 14 Mar 2022 14:18:47-_jb_pytest_runner.py-test_InstanceCase.py-[line:38]-INFO-[日志信息]: 当前用例预期结果：{'code': 'Success', 'msg': ''}
Mon, 14 Mar 2022 14:18:47-_jb_pytest_runner.py-test_InstanceCase.py-[line:39]-INFO-[日志信息]: 当前用例实际结果：{'code': 'Success', 'data': 'f94411a60c-df3185ed', 'msg': ''}

Mon, 14 Mar 2022 14:18:48-_jb_pytest_runner.py-test_InstanceCase.py-[line:36]-INFO-[日志信息]: 当前用例名称：创建实例时GPU不足
Mon, 14 Mar 2022 14:18:48-_jb_pytest_runner.py-test_InstanceCase.py-[line:37]-INFO-[日志信息]: 当前测试用例请求参数：{'instance_info': {'charge_type': 'payg', 'image': 'hub.kce.ksyun.com/autodl-image/torch:cuda11.0-cudnn8-devel-ubuntu18.04-py38-torch1.7.0', 'machine_id': 'None', 'instance_name': '', 'req_gpu_amount': 1}, 'price_info': {'charge_type': 'payg', 'duration': 1, 'machine_id': 'None', 'num': 1}}
Mon, 14 Mar 2022 14:18:48-_jb_pytest_runner.py-test_InstanceCase.py-[line:38]-INFO-[日志信息]: 当前用例预期结果：{'code': 'InternalError', 'msg': '机器空闲GPU不足'}
Mon, 14 Mar 2022 14:18:48-_jb_pytest_runner.py-test_InstanceCase.py-[line:39]-INFO-[日志信息]: 当前用例实际结果：{'code': 'DatabaseError', 'data': None, 'msg': '服务异常，请稍后重试', 'debug_error': ''}

Mon, 14 Mar 2022 14:18:48-_jb_pytest_runner.py-Assert.py-[line:110]-ERROR-[日志信息]: Traceback (most recent call last):
  File "C:\Users\张铁瀛\PycharmProjects\API_AUTO\common\Assert.py", line 104, in define_assert
    assert res['code'] == respData['code']
AssertionError: assert 'DatabaseError' == 'InternalError'

Mon, 14 Mar 2022 14:18:48-_jb_pytest_runner.py-test_InstanceCase.py-[line:43]-ERROR-[日志信息]: 用例执行失败assert 'DatabaseError' == 'InternalError'
Mon, 14 Mar 2022 14:19:34-_jb_pytest_runner.py-test_InstanceCase.py-[line:36]-INFO-[日志信息]: 当前用例名称：正确创建实例
Mon, 14 Mar 2022 14:19:34-_jb_pytest_runner.py-test_InstanceCase.py-[line:37]-INFO-[日志信息]: 当前测试用例请求参数：{'instance_info': {'charge_type': 'payg', 'image': 'hub.kce.ksyun.com/autodl-image/torch:cuda11.0-cudnn8-devel-ubuntu18.04-py38-torch1.7.0', 'machine_id': 'f94411a60c', 'instance_name': '', 'req_gpu_amount': 1}, 'price_info': {'charge_type': 'payg', 'duration': 1, 'machine_id': 'f94411a60c', 'num': 1}}
Mon, 14 Mar 2022 14:19:34-_jb_pytest_runner.py-test_InstanceCase.py-[line:38]-INFO-[日志信息]: 当前用例预期结果：{'code': 'Success', 'msg': ''}
Mon, 14 Mar 2022 14:19:34-_jb_pytest_runner.py-test_InstanceCase.py-[line:39]-INFO-[日志信息]: 当前用例实际结果：{'code': 'Success', 'data': 'f94411a60c-0b1960fc', 'msg': ''}

Mon, 14 Mar 2022 14:19:34-_jb_pytest_runner.py-test_InstanceCase.py-[line:36]-INFO-[日志信息]: 当前用例名称：创建实例时GPU不足
Mon, 14 Mar 2022 14:19:34-_jb_pytest_runner.py-test_InstanceCase.py-[line:37]-INFO-[日志信息]: 当前测试用例请求参数：{'instance_info': {'charge_type': 'payg', 'image': 'hub.kce.ksyun.com/autodl-image/torch:cuda11.0-cudnn8-devel-ubuntu18.04-py38-torch1.7.0', 'machine_id': 'None', 'instance_name': '', 'req_gpu_amount': 1}, 'price_info': {'charge_type': 'payg', 'duration': 1, 'machine_id': 'None', 'num': 1}}
Mon, 14 Mar 2022 14:19:34-_jb_pytest_runner.py-test_InstanceCase.py-[line:38]-INFO-[日志信息]: 当前用例预期结果：{'code': 'InternalError', 'msg': '机器空闲GPU不足'}
Mon, 14 Mar 2022 14:19:34-_jb_pytest_runner.py-test_InstanceCase.py-[line:39]-INFO-[日志信息]: 当前用例实际结果：{'code': 'DatabaseError', 'data': None, 'msg': '服务异常，请稍后重试', 'debug_error': ''}

Mon, 14 Mar 2022 14:19:34-_jb_pytest_runner.py-Assert.py-[line:110]-ERROR-[日志信息]: Traceback (most recent call last):
  File "C:\Users\张铁瀛\PycharmProjects\API_AUTO\common\Assert.py", line 104, in define_assert
    assert res['code'] == respData['code']
AssertionError: assert 'DatabaseError' == 'InternalError'

Mon, 14 Mar 2022 14:19:34-_jb_pytest_runner.py-test_InstanceCase.py-[line:43]-ERROR-[日志信息]: 用例执行失败assert 'DatabaseError' == 'InternalError'
Mon, 14 Mar 2022 15:25:20-_jb_pytest_runner.py-test_InstanceCase.py-[line:39]-INFO-[日志信息]: 当前用例名称：正确创建实例
Mon, 14 Mar 2022 15:25:20-_jb_pytest_runner.py-test_InstanceCase.py-[line:40]-INFO-[日志信息]: 当前测试用例请求参数：{'instance_info': {'charge_type': 'payg', 'image': 'hub.kce.ksyun.com/autodl-image/torch:cuda11.0-cudnn8-devel-ubuntu18.04-py38-torch1.7.0', 'machine_id': 'f94411a60c', 'instance_name': '', 'req_gpu_amount': 1}, 'price_info': {'charge_type': 'payg', 'duration': 1, 'machine_id': 'f94411a60c', 'num': 1}}
Mon, 14 Mar 2022 15:25:20-_jb_pytest_runner.py-test_InstanceCase.py-[line:41]-INFO-[日志信息]: 当前用例预期结果：{'code': 'Success', 'msg': ''}
Mon, 14 Mar 2022 15:25:20-_jb_pytest_runner.py-test_InstanceCase.py-[line:42]-INFO-[日志信息]: 当前用例实际结果：{'code': 'Success', 'data': 'f94411a60c-9c6cf154', 'msg': ''}

Mon, 14 Mar 2022 15:25:20-_jb_pytest_runner.py-test_InstanceCase.py-[line:39]-INFO-[日志信息]: 当前用例名称：创建实例时GPU不足
Mon, 14 Mar 2022 15:25:20-_jb_pytest_runner.py-test_InstanceCase.py-[line:40]-INFO-[日志信息]: 当前测试用例请求参数：{'instance_info': {'charge_type': 'payg', 'image': 'hub.kce.ksyun.com/autodl-image/torch:cuda11.0-cudnn8-devel-ubuntu18.04-py38-torch1.7.0', 'machine_id': 'None', 'instance_name': '', 'req_gpu_amount': 1}, 'price_info': {'charge_type': 'payg', 'duration': 1, 'machine_id': 'None', 'num': 1}}
Mon, 14 Mar 2022 15:25:20-_jb_pytest_runner.py-test_InstanceCase.py-[line:41]-INFO-[日志信息]: 当前用例预期结果：{'code': 'InternalError', 'msg': '机器空闲GPU不足'}
Mon, 14 Mar 2022 15:25:20-_jb_pytest_runner.py-test_InstanceCase.py-[line:42]-INFO-[日志信息]: 当前用例实际结果：{'code': 'DatabaseError', 'data': None, 'msg': '服务异常，请稍后重试', 'debug_error': ''}

Mon, 14 Mar 2022 15:25:20-_jb_pytest_runner.py-Assert.py-[line:110]-ERROR-[日志信息]: Traceback (most recent call last):
  File "C:\Users\张铁瀛\PycharmProjects\API_AUTO\common\Assert.py", line 104, in define_assert
    assert res['code'] == respData['code']
AssertionError: assert 'DatabaseError' == 'InternalError'

Mon, 14 Mar 2022 15:25:20-_jb_pytest_runner.py-test_InstanceCase.py-[line:46]-ERROR-[日志信息]: 用例执行失败assert 'DatabaseError' == 'InternalError'
Mon, 14 Mar 2022 17:08:23-_jb_pytest_runner.py-test_LoginCase.py-[line:27]-INFO-[日志信息]: 当前用例名称：手机号密码都正确
Mon, 14 Mar 2022 17:08:23-_jb_pytest_runner.py-test_LoginCase.py-[line:28]-INFO-[日志信息]: 当前测试用例请求参数：{'phone': '18801053303', 'password': 'a753c776ff3ed4fefa2af948af87448910153281', 'captcha_id': '111'}
Mon, 14 Mar 2022 17:08:23-_jb_pytest_runner.py-test_LoginCase.py-[line:29]-INFO-[日志信息]: 当前用例预期结果：{'code': 'Success', 'msg': ''}
Mon, 14 Mar 2022 17:08:23-_jb_pytest_runner.py-test_LoginCase.py-[line:30]-INFO-[日志信息]: 当前用例实际结果：{'code': 'Success', 'data': {'ticket': 'd95o2uzYI7q7tY7bHI4U1xBug7s=', 'user': {'id': 3, 'created_at': '2021-08-06T21:36:59+08:00', 'updated_at': '2021-09-14T10:40:09+08:00', 'uuid': '487686b5-637f-4d99-8202-7c0b29fa322d', 'username': 'zty_tester', 'nickname': 'ZhangTy', 'status': 'normal', 'logged_in_at': '2022-03-10T10:58:48.637+08:00', 'email': '', 'phone': '18801053303', 'is_admin': False, 'is_super_admin': False, 'sha1_password': 'a753c776ff3ed4fefa2af948af87448910153281', 'email_confirmed': False, 'idle_job_authority': True, 'mount_net_disk_authority': True, 'invitation_code': '', 'open_id': '111', 'union_id': '', 'applet_open_id': '', 'avatar_id': 0, 'register_ip': '', 'growth_value': -251000, 'member_level': 'normal_user', 'level_acq_mode': 'vip_user_acquire', 'member_dateline': None}}, 'msg': ''}

Mon, 14 Mar 2022 17:08:23-_jb_pytest_runner.py-test_LoginCase.py-[line:27]-INFO-[日志信息]: 当前用例名称：手机号正确，密码错误
Mon, 14 Mar 2022 17:08:23-_jb_pytest_runner.py-test_LoginCase.py-[line:28]-INFO-[日志信息]: 当前测试用例请求参数：{'phone': '18801053303', 'password': '40bd001563085fc35165329ea1ff5c5ecbdbbeef'}
Mon, 14 Mar 2022 17:08:23-_jb_pytest_runner.py-test_LoginCase.py-[line:29]-INFO-[日志信息]: 当前用例预期结果：{'code': 'RequestParameterIsWrong', 'msg': '手机号或密码错误，请重试'}
Mon, 14 Mar 2022 17:08:23-_jb_pytest_runner.py-test_LoginCase.py-[line:30]-INFO-[日志信息]: 当前用例实际结果：{'code': 'RequestParameterIsWrong', 'data': 1, 'msg': '手机号或密码错误，请重试', 'debug_error': ''}

Mon, 14 Mar 2022 17:08:23-_jb_pytest_runner.py-test_LoginCase.py-[line:27]-INFO-[日志信息]: 当前用例名称：手机号错误，密码正确
Mon, 14 Mar 2022 17:08:23-_jb_pytest_runner.py-test_LoginCase.py-[line:28]-INFO-[日志信息]: 当前测试用例请求参数：{'phone': '188010533', 'password': 'a753c776ff3ed4fefa2af948af87448910153281'}
Mon, 14 Mar 2022 17:08:23-_jb_pytest_runner.py-test_LoginCase.py-[line:29]-INFO-[日志信息]: 当前用例预期结果：{'code': 'RequestParameterIsWrong', 'msg': '手机号或密码错误，请重试'}
Mon, 14 Mar 2022 17:08:23-_jb_pytest_runner.py-test_LoginCase.py-[line:30]-INFO-[日志信息]: 当前用例实际结果：{'code': 'RequestParameterIsWrong', 'data': 1, 'msg': '手机号或密码错误，请重试', 'debug_error': ''}

Mon, 14 Mar 2022 17:08:23-_jb_pytest_runner.py-test_LoginCase.py-[line:27]-INFO-[日志信息]: 当前用例名称：手机号错误，密码错误
Mon, 14 Mar 2022 17:08:23-_jb_pytest_runner.py-test_LoginCase.py-[line:28]-INFO-[日志信息]: 当前测试用例请求参数：{'phone': '18801053124', 'password': 'a8ef6091e7aded9675e79ff635ffd80e8c780420'}
Mon, 14 Mar 2022 17:08:23-_jb_pytest_runner.py-test_LoginCase.py-[line:29]-INFO-[日志信息]: 当前用例预期结果：{'code': 'RequestParameterIsWrong', 'msg': '手机号或密码错误，请重试'}
Mon, 14 Mar 2022 17:08:23-_jb_pytest_runner.py-test_LoginCase.py-[line:30]-INFO-[日志信息]: 当前用例实际结果：{'code': 'RequestParameterIsWrong', 'data': 1, 'msg': '手机号或密码错误，请重试', 'debug_error': ''}

Mon, 14 Mar 2022 17:08:24-_jb_pytest_runner.py-test_LoginCase.py-[line:27]-INFO-[日志信息]: 当前用例名称：手机号输入9位，密码输入正确
Mon, 14 Mar 2022 17:08:24-_jb_pytest_runner.py-test_LoginCase.py-[line:28]-INFO-[日志信息]: 当前测试用例请求参数：{'phone': '188010500', 'password': 'a753c776ff3ed4fefa2af948af87448910153281'}
Mon, 14 Mar 2022 17:08:24-_jb_pytest_runner.py-test_LoginCase.py-[line:29]-INFO-[日志信息]: 当前用例预期结果：{'code': 'RequestParameterIsWrong', 'msg': '手机号或密码错误，请重试'}
Mon, 14 Mar 2022 17:08:24-_jb_pytest_runner.py-test_LoginCase.py-[line:30]-INFO-[日志信息]: 当前用例实际结果：{'code': 'RequestParameterIsWrong', 'data': 1, 'msg': '手机号或密码错误，请重试', 'debug_error': ''}

Mon, 14 Mar 2022 17:08:24-_jb_pytest_runner.py-test_LoginCase.py-[line:27]-INFO-[日志信息]: 当前用例名称：手机号输入12位，密码输入正确
Mon, 14 Mar 2022 17:08:24-_jb_pytest_runner.py-test_LoginCase.py-[line:28]-INFO-[日志信息]: 当前测试用例请求参数：{'phone': '188010500001', 'password': 'a753c776ff3ed4fefa2af948af87448910153281'}
Mon, 14 Mar 2022 17:08:24-_jb_pytest_runner.py-test_LoginCase.py-[line:29]-INFO-[日志信息]: 当前用例预期结果：{'code': 'RequestParameterIsWrong', 'msg': '手机号或密码错误，请重试'}
Mon, 14 Mar 2022 17:08:24-_jb_pytest_runner.py-test_LoginCase.py-[line:30]-INFO-[日志信息]: 当前用例实际结果：{'code': 'RequestParameterIsWrong', 'data': 1, 'msg': '手机号或密码错误，请重试', 'debug_error': ''}

Mon, 14 Mar 2022 17:08:24-_jb_pytest_runner.py-test_LoginCase.py-[line:27]-INFO-[日志信息]: 当前用例名称：密码输入7位，手机号输入正确
Mon, 14 Mar 2022 17:08:24-_jb_pytest_runner.py-test_LoginCase.py-[line:28]-INFO-[日志信息]: 当前测试用例请求参数：{'phone': '188010500001', 'password': '20eabe5d64b0e216796e834f52d61fd0b70332fc'}
Mon, 14 Mar 2022 17:08:24-_jb_pytest_runner.py-test_LoginCase.py-[line:29]-INFO-[日志信息]: 当前用例预期结果：{'code': 'RequestParameterIsWrong', 'msg': '手机号或密码错误，请重试'}
Mon, 14 Mar 2022 17:08:24-_jb_pytest_runner.py-test_LoginCase.py-[line:30]-INFO-[日志信息]: 当前用例实际结果：{'code': 'RequestParameterIsWrong', 'data': 2, 'msg': '手机号或密码错误，请重试', 'debug_error': ''}

Mon, 14 Mar 2022 17:08:24-_jb_pytest_runner.py-test_LoginCase.py-[line:27]-INFO-[日志信息]: 当前用例名称：密码输入17位，手机号输入正确
Mon, 14 Mar 2022 17:08:24-_jb_pytest_runner.py-test_LoginCase.py-[line:28]-INFO-[日志信息]: 当前测试用例请求参数：{'phone': '188010500001', 'password': 'f6cff2998c2f0fd52fb0e9891d10ca3b0cb41fc1'}
Mon, 14 Mar 2022 17:08:24-_jb_pytest_runner.py-test_LoginCase.py-[line:29]-INFO-[日志信息]: 当前用例预期结果：{'code': 'RequestParameterIsWrong', 'msg': '手机号或密码错误，请重试'}
Mon, 14 Mar 2022 17:08:24-_jb_pytest_runner.py-test_LoginCase.py-[line:30]-INFO-[日志信息]: 当前用例实际结果：{'code': 'RequestParameterIsWrong', 'data': 3, 'msg': '手机号或密码错误，请重试', 'debug_error': ''}

Mon, 14 Mar 2022 17:08:24-_jb_pytest_runner.py-test_LoginCase.py-[line:27]-INFO-[日志信息]: 当前用例名称：密码输入17位，手机号输入正确
Mon, 14 Mar 2022 17:08:24-_jb_pytest_runner.py-test_LoginCase.py-[line:28]-INFO-[日志信息]: 当前测试用例请求参数：{'phone': '188010500001', 'password': 'f6cff2998c2f0fd52fb0e9891d10ca3b0cb41fc1'}
Mon, 14 Mar 2022 17:08:24-_jb_pytest_runner.py-test_LoginCase.py-[line:29]-INFO-[日志信息]: 当前用例预期结果：{'code': 'RequestParameterIsWrong', 'msg': '手机号或密码错误，请重试'}
Mon, 14 Mar 2022 17:08:24-_jb_pytest_runner.py-test_LoginCase.py-[line:30]-INFO-[日志信息]: 当前用例实际结果：{'code': 'RequestParameterIsWrong', 'data': 4, 'msg': '手机号或密码错误，请重试', 'debug_error': ''}

Mon, 14 Mar 2022 17:08:24-_jb_pytest_runner.py-test_LoginCase.py-[line:27]-INFO-[日志信息]: 当前用例名称：手机号输入英文+汉字，密码输入正确
Mon, 14 Mar 2022 17:08:24-_jb_pytest_runner.py-test_LoginCase.py-[line:28]-INFO-[日志信息]: 当前测试用例请求参数：{'phone': 'test登录', 'password': 'a8ef6091e7aded9675e79ff635ffd80e8c780420'}
Mon, 14 Mar 2022 17:08:24-_jb_pytest_runner.py-test_LoginCase.py-[line:29]-INFO-[日志信息]: 当前用例预期结果：{'code': 'RequestParameterIsWrong', 'msg': '手机号或密码错误，请重试'}
Mon, 14 Mar 2022 17:08:24-_jb_pytest_runner.py-test_LoginCase.py-[line:30]-INFO-[日志信息]: 当前用例实际结果：{'code': 'RequestParameterIsWrong', 'data': 1, 'msg': '手机号或密码错误，请重试', 'debug_error': ''}

Mon, 14 Mar 2022 17:08:25-_jb_pytest_runner.py-test_LoginCase.py-[line:27]-INFO-[日志信息]: 当前用例名称：不输入手机号，密码输入正确
Mon, 14 Mar 2022 17:08:25-_jb_pytest_runner.py-test_LoginCase.py-[line:28]-INFO-[日志信息]: 当前测试用例请求参数：{'phone': '', 'password': 'a8ef6091e7aded9675e79ff635ffd80e8c780420'}
Mon, 14 Mar 2022 17:08:25-_jb_pytest_runner.py-test_LoginCase.py-[line:29]-INFO-[日志信息]: 当前用例预期结果：{'code': 'RequestParameterIsWrong', 'msg': '手机号或密码错误，请重试'}
Mon, 14 Mar 2022 17:08:25-_jb_pytest_runner.py-test_LoginCase.py-[line:30]-INFO-[日志信息]: 当前用例实际结果：{'code': 'RequestParameterIsWrong', 'data': None, 'msg': '请求参数错误', 'debug_error': ''}

Mon, 14 Mar 2022 17:08:25-_jb_pytest_runner.py-test_LoginCase.py-[line:27]-INFO-[日志信息]: 当前用例名称：不输入密码，手机号输入正确
Mon, 14 Mar 2022 17:08:25-_jb_pytest_runner.py-test_LoginCase.py-[line:28]-INFO-[日志信息]: 当前测试用例请求参数：{'phone': '18801053303', 'password': 'da39a3ee5e6b4b0d3255bfef95601890afd80709'}
Mon, 14 Mar 2022 17:08:25-_jb_pytest_runner.py-test_LoginCase.py-[line:29]-INFO-[日志信息]: 当前用例预期结果：{'code': 'RequestParameterIsWrong', 'msg': '手机号或密码错误，请重试'}
Mon, 14 Mar 2022 17:08:25-_jb_pytest_runner.py-test_LoginCase.py-[line:30]-INFO-[日志信息]: 当前用例实际结果：{'code': 'RequestParameterIsWrong', 'data': 2, 'msg': '手机号或密码错误，请重试', 'debug_error': ''}

Mon, 14 Mar 2022 17:08:25-_jb_pytest_runner.py-test_LoginCase.py-[line:27]-INFO-[日志信息]: 当前用例名称：手机号输入特殊符号
Mon, 14 Mar 2022 17:08:25-_jb_pytest_runner.py-test_LoginCase.py-[line:28]-INFO-[日志信息]: 当前测试用例请求参数：{'phone': '！@#￥%……&*（)', 'password': 'da39a3ee5e6b4b0d3255bfef95601890afd80709'}
Mon, 14 Mar 2022 17:08:25-_jb_pytest_runner.py-test_LoginCase.py-[line:29]-INFO-[日志信息]: 当前用例预期结果：{'code': 'RequestParameterIsWrong', 'msg': '手机号或密码错误，请重试'}
Mon, 14 Mar 2022 17:08:25-_jb_pytest_runner.py-test_LoginCase.py-[line:30]-INFO-[日志信息]: 当前用例实际结果：{'code': 'RequestParameterIsWrong', 'data': 1, 'msg': '手机号或密码错误，请重试', 'debug_error': ''}

Mon, 14 Mar 2022 17:08:25-_jb_pytest_runner.py-test_LoginCase.py-[line:27]-INFO-[日志信息]: 当前用例名称：手机号输入null 密码不输入
Mon, 14 Mar 2022 17:08:25-_jb_pytest_runner.py-test_LoginCase.py-[line:28]-INFO-[日志信息]: 当前测试用例请求参数：{'phone': 'Null', 'password': 'da39a3ee5e6b4b0d3255bfef95601890afd80709'}
Mon, 14 Mar 2022 17:08:25-_jb_pytest_runner.py-test_LoginCase.py-[line:29]-INFO-[日志信息]: 当前用例预期结果：{'code': 'RequestParameterIsWrong', 'msg': '手机号或密码错误，请重试'}
Mon, 14 Mar 2022 17:08:25-_jb_pytest_runner.py-test_LoginCase.py-[line:30]-INFO-[日志信息]: 当前用例实际结果：{'code': 'RequestParameterIsWrong', 'data': 1, 'msg': '手机号或密码错误，请重试', 'debug_error': ''}

Mon, 14 Mar 2022 17:08:25-_jb_pytest_runner.py-test_LoginCase.py-[line:27]-INFO-[日志信息]: 当前用例名称：密码输入null 手机号不输入
Mon, 14 Mar 2022 17:08:25-_jb_pytest_runner.py-test_LoginCase.py-[line:28]-INFO-[日志信息]: 当前测试用例请求参数：{'phone': '', 'password': '109085beaaa80ac89858b283a64f7c75d7e5bb12'}
Mon, 14 Mar 2022 17:08:25-_jb_pytest_runner.py-test_LoginCase.py-[line:29]-INFO-[日志信息]: 当前用例预期结果：{'code': 'RequestParameterIsWrong', 'msg': '手机号或密码错误，请重试'}
Mon, 14 Mar 2022 17:08:25-_jb_pytest_runner.py-test_LoginCase.py-[line:30]-INFO-[日志信息]: 当前用例实际结果：{'code': 'RequestParameterIsWrong', 'data': None, 'msg': '请求参数错误', 'debug_error': ''}

Mon, 14 Mar 2022 17:08:25-_jb_pytest_runner.py-test_LoginCase.py-[line:27]-INFO-[日志信息]: 当前用例名称：手机号输入null 密码输入null
Mon, 14 Mar 2022 17:08:25-_jb_pytest_runner.py-test_LoginCase.py-[line:28]-INFO-[日志信息]: 当前测试用例请求参数：{'phone': '', 'password': '109085beaaa80ac89858b283a64f7c75d7e5bb12'}
Mon, 14 Mar 2022 17:08:25-_jb_pytest_runner.py-test_LoginCase.py-[line:29]-INFO-[日志信息]: 当前用例预期结果：{'code': 'RequestParameterIsWrong', 'msg': '手机号或密码错误，请重试'}
Mon, 14 Mar 2022 17:08:25-_jb_pytest_runner.py-test_LoginCase.py-[line:30]-INFO-[日志信息]: 当前用例实际结果：{'code': 'RequestParameterIsWrong', 'data': None, 'msg': '请求参数错误', 'debug_error': ''}

Mon, 14 Mar 2022 17:08:26-_jb_pytest_runner.py-test_LoginCase.py-[line:27]-INFO-[日志信息]: 当前用例名称：输入sql语句
Mon, 14 Mar 2022 17:08:26-_jb_pytest_runner.py-test_LoginCase.py-[line:28]-INFO-[日志信息]: 当前测试用例请求参数：{'phone': 'select username，password from user where username=', 'password': 'e693f99fbb5efd10efe806601ff8bfebb64a4343'}
Mon, 14 Mar 2022 17:08:26-_jb_pytest_runner.py-test_LoginCase.py-[line:29]-INFO-[日志信息]: 当前用例预期结果：{'code': 'RequestParameterIsWrong', 'msg': '手机号或密码错误，请重试'}
Mon, 14 Mar 2022 17:08:26-_jb_pytest_runner.py-test_LoginCase.py-[line:30]-INFO-[日志信息]: 当前用例实际结果：{'code': 'RequestParameterIsWrong', 'data': 1, 'msg': '手机号或密码错误，请重试', 'debug_error': ''}

